Workbook

Sheet База
A2: №п/п | B2: Гос.№ | C2: Гараж.№ | D2: участок | E2: Модель техники | F2: WIN | G2: Май | J2: Июнь | M2: Июль | P2: Август | S2: Сентябрь | V2: Октябрь | Y2: Ноябрь | AB2: Декабрь
G3: 1-10 | H3: 11-20 | I3: 21-31 | J3: 1-10 | K3: 11-20 | L3: 21-30 | M3: 1-10 | N3: 11-20 | O3: 21-31 | P3: 1-10 | Q3: 11-20 | R3: 21-31 | S3: 1-10 | T3: 11-20 | U3: 21-30 | V3: 1-10 | W3: 11-20 | X3: 21-31 | Y3: 1-10 | Z3: 11-20 | AA3: 21-30 | AB3: 1-10 | AC3: 11-20 | AD3: 21-31
B4: База
A5: 1 | D5: База | E5: Камаз65116
A6: 2 | D6: База | E6: M/B 313cdi
A7: 3 | D7: База | E7: M/B 1840i
A8: 4 | D8: База | E8: HD65
A9: 5 | B9: 024BS 03 | D9: База | E9: Isuzu NHR55E
A10: 6 | B10: AEDC 385 | D10: База | E10: Пр-п НЕХ 9390 (трал)
A11: 7 | B11: 4019 | D11: База | E11: П/пр-п трал
A12: 8 | B12: AKD503C | D12: База | E12: Погрузчик ZL50G

Sheet Ник-ка
A1: №п/п | B1: Гос.№ | C1: Гараж.№ | D1: участок | E1: Модель техники | F1: WIN | G1: Текущие м.ч. | H1: Май | K1: Июнь | N1: Июль | Q1: Август | T1: Сентябрь | W1: Октябрь | Z1: Ноябрь | AC1: Декабрь
H2: 1-10 | I2: 11-20 | J2: 21-31 | K2: 1-10 | L2: 11-20 | M2: 21-30 | N2: 1-10 | O2: 11-20 | P2: 21-31 | Q2: 1-10 | R2: 11-20 | S2: 21-31 | T2: 1-10 | U2: 11-20 | V2: 21-30 | W2: 1-10 | X2: 11-20 | Y2: 21-31 | Z2: 1-10 | AA2: 11-20 | AB2: 21-30 | AC2: 1-10 | AD2: 11-20 | AE2: 21-31
H3: Вид ТО | K3: Вид ТО | N3: Вид ТО | Q3: Вид ТО | T3: Вид ТО | W3: Вид ТО | Z3: Вид ТО | AC3: Вид ТО
A4: Николаевка
A5: Самосвалы
A6: 1 | B6: 311BS 03 | D6: Ник-ка | E6: IVECO AMT653301
A7: 2 | B7: 860DH 01 | C7: 56 | D7: Ник-ка | E7: IVECO AMT653301
A8: 3 | B8: 257 DF 01 | C8: 184 | D8: Ник-ка | G8: ='Актуальные м.ч.'!E71 -> 46526
A9: Топливозаправщики
A10: 4 | B10: 490BS 03 | D10: Ник-ка | E10: Камаз 43106
A11: 5 | B11: 27 | D11: Ник-ка | E11: Урал 4320
A12: Вспомогательные машины
A13: 6 | B13: 350АР 03 | D13: Ник-ка | E13: УАЗ390902
A14: 7 | B14: 859DH 01 | D14: Ник-ка | E14: УАЗ390903
A15: 8 | D15: Ник-ка | E15: УАЗ
A16: 9 | D16: Ник-ка | E16: УАЗ
A17: 10 | B17: 117 | D17: Ник-ка | E17: ПАЗ4324
A18: 11 | D18: Ник-ка | E18: SYZUKI
A19: 12 | D19: Ник-ка | E19: Mitsybishi L200
A20: 13 | D20: Ник-ка | E20: Mitsybishi L200
A21: 14 | E21: Соболь
A22: 15 | E22: УАЗ
A23: Погрузчики
A24: 16 | B24: AED892C | C24: 404 | D24: Ник-ка | E24: Погрузчик SDLG L975F | G24: ='Актуальные м.ч.'!E65 -> 12341 | I24: ТО-400 17.05.26 | K24: ТО-800 06.06.26 | M24: ТО-400 26.06.26 | O24: ТО-1600 16.07.26 | Q24: ТО-2000 05.08.26 | S24: ТО-400 25.08.26 | U24: ТО-800 14.09.26 | W24: ТО-400 04.10.26 | Y24: ТО-1600 24.10.26 | AA24: ТО-2000 13.11.26 | AC24: ТО-400 03.12.26 | AE24: ТО-800 23.12.26
A25: Автогрейдеры
A26: 17 | B26: ALD917C | C26: 401 | D26: Ник-ка | E26: автогрейдер SANY STG210C-8S | G26: ='Актуальные м.ч.'!E61 -> 16449 | I26: ТО-500 15.05.26 | K26: ТО-1000 09.06.26 | N26: ТО-500 04.07.26 | P26: ТО-2000 29.07.26 | S26: ТО-500 23.08.26 | U26: ТО-1000 17.09.26 | X26: ТО-500 12.10.26 | Z26: ТО-2000 06.11.26 | AC26: ТО-500 01.12.26 | AE26: ТО-1000 26.12.26
A27: 18 | B27: ALD848C | C27: 402 | D27: Ник-ка | E27: автогрейдер SANY STG210C-8S | G27: ='Актуальные м.ч.'!E62 -> 10684 | I27: ТО-500 14.05.26 | K27: ТО-1000 08.06.26 | N27: ТО-500 03.07.26 | P27: ТО-2000 28.07.26 | S27: ТО-500 22.08.26 | U27: ТО-1000 16.09.26 | X27: ТО-500 11.10.26 | Z27: ТО-2000 05.11.26 | AB27: ТО-500 30.11.26 | AE27: ТО-1000 25.12.26
A28: 19 | C28: 408 | D28: Ник-ка | E28: автогрейдер SANY STG210C-8S | G28: ='Актуальные м.ч.'!E63 -> 2725 | J28: ТО-250 25.05.26 | K28: ТО-1000 06.06.26 | L28: ТО-250 19.06.26 | N28: ТО-500 01.07.26 | O28: ТО-250 14.07.26 | P28: ТО-2000 26.07.26 | Q28: ТО-250 08.08.26 | R28: ТО-500 20.08.26 | T28: ТО-250 02.09.26 | U28: ТО-1000 14.09.26 | V28: ТО-250 27.09.26 | W28: ТО-500 09.10.26 | Y28: ТО-250 22.10.26 | Z28: ТО-2000 03.11.26 | AA28: ТО-250 16.11.26 | AB28: ТО-500 28.11.26 | AD28: ТО-250 11.12.26 | AE28: ТО-1000 23.12.26
A29: Самосвалы
A30: 20 | B30: 572CAUD | C30: 101 | D30: Ник-ка | E30: XCMG XGA5902D3T самосвал | F30: LC1ARMAF6M0700049 | G30: ='Актуальные м.ч.'!E21 -> 15243 | J30: ТО-500 31.05.26 | M30: ТО-2000 25.06.26 | O30: ТО-500 20.07.26 | R30: ТО-1000 14.08.26 | T30: ТО-500 08.09.26 | W30: ТО-2000 03.10.26 | Y30: ТО-500 28.10.26 | AB30: ТО-1000 22.11.26 | AD30: ТО-500 17.12.26
A31: 21 | B31: 574CAUD | C31: 102 | D31: Ник-ка | E31: XCMG XGA5902D3T самосвал | F31: LC1ARMAF4M0700048
A32: 22 | B32: 577CAUD | C32: 103 | D32: Ник-ка | E32: XCMG XGA5902D3T самосвал | F32: LC1ARMAF1M0700038 | G32: ='Актуальные м.ч.'!E22 -> 17047 | K32: ТО-500 04.06.26 | M32: ТО-2000 29.06.26 | P32: ТО-500 24.07.26 | R32: ТО-1000 18.08.26 | U32: ТО-500 12.09.26 | W32: ТО-2000 07.10.26 | Z32: ТО-500 01.11.26 | AB32: ТО-1000 26.11.26 | AE32: ТО-500 21.12.26
A33: 23 | B33: 533CAUD | C33: 104 | D33: Ник-ка | E33: XCMG XGA5902D3T самосвал | F33: LC1ARMAF2M0700047 | G33: ='Актуальные м.ч.'!E23 -> 13936 | J33: ТО-2000 26.05.26 | K33: ТО-250 07.06.26 | L33: ТО-500 20.06.26 | N33: ТО-250 02.07.26 | O33: ТО-1000 15.07.26 | P33: ТО-250 27.07.26 | Q33: ТО-500 09.08.26 | S33: ТО-250 21.08.26 | T33: ТО-1000 03.09.26 | U33: ТО-250 15.09.26 | V33: ТО-500 28.09.26 | W33: ТО-250 10.10.26 | Y33: ТО-1000 23.10.26 | Z33: ТО-250 04.11.26 | AA33: ТО-500 17.11.26 | AB33: ТО-250 29.11.26 | AD33: ТО-1000 12.12.26 | AE33: ТО-250 24.12.26
A34: 24 | B34: 576CAUD | C34: 105 | D34: Ник-ка | E34: XCMG XGA5902D3T самосвал | F34: LC1ARMAF0M0700046 | G34: ='Актуальные м.ч.'!E24 -> 13091 | I34: ТО-1000 14.05.26 | K34: ТО-500 08.06.26 | N34: ТО-2000 03.07.26 | P34: ТО-500 28.07.26 | S34: ТО-1000 22.08.26 | U34: ТО-500 16.09.26 | X34: ТО-2000 11.10.26 | Z34: ТО-500 05.11.26 | AB34: ТО-1000 30.11.26 | AE34: ТО-500 25.12.26
A35: 25 | C35: 106 | D35: Ник-ка | E35: XCMG XGA5902D3T самосвал | F35: LC1ARMAF6M0701511 | G35: ='Актуальные м.ч.'!E25 -> 12866 | J35: ТО-1000 28.05.26 | K35: ТО-250 09.06.26 | M35: ТО-500 22.06.26 | N35: ТО-250 04.07.26 | O35: ТО-1000 17.07.26 | P35: ТО-250 29.07.26 | R35: ТО-500 11.08.26 | S35: ТО-250 23.08.26 | T35: ТО-1000 05.09.26 | U35: ТО-250 17.09.26 | V35: ТО-500 30.09.26 | X35: ТО-250 12.10.26 | Y35: ТО-1000 25.10.26 | Z35: ТО-250 06.11.26 | AA35: ТО-500 19.11.26 | AC35: ТО-250 01.12.26 | AD35: ТО-1000 14.12.26 | AE35: ТО-250 26.12.26
A36: 26 | C36: 107 | D36: Ник-ка | E36: XCMG XGA5902D3T самосвал | F36: LC1ARMAF1M0701501
A37: 27 | C37: 108 | D37: Ник-ка | E37: XCMG XGA5902D3T самосвал | F37: LC1ARMAF3M0702016 | G37: ='Актуальные м.ч.'!E26 -> 10488 | I37: ТО-500 13.05.26 | K37: ТО-1000 07.06.26 | N37: ТО-500 02.07.26 | P37: ТО-2000 27.07.26 | S37: ТО-500 21.08.26 | U37: ТО-1000 15.09.26 | W37: ТО-500 10.10.26 | Z37: ТО-2000 04.11.26 | AB37: ТО-500 29.11.26 | AE37: ТО-1000 24.12.26
A38: 28 | C38: 109 | D38: Ник-ка | E38: XCMG XGA5902D3T самосвал | F38: LC1ARMAF5M0702018 | G38: ='Актуальные м.ч.'!E27 -> 11834 | J38: ТО-2000 21.05.26 | L38: ТО-500 15.06.26 | N38: ТО-1000 10.07.26 | Q38: ТО-500 04.08.26 | S38: ТО-2000 29.08.26 | V38: ТО-500 23.09.26 | X38: ТО-1000 18.10.26 | AA38: ТО-500 12.11.26 | AC38: ТО-2000 07.12.26
A39: 29 | C39: 110 | D39: Ник-ка | E39: XCMG XGA5902D3T самосвал | F39: LC1ARMAF2N0701118 | G39: ='Актуальные м.ч.'!E28 -> 14657 | I39: ТО-500 15.05.26 | K39: ТО-1000 09.06.26 | N39: ТО-500 04.07.26 | P39: ТО-2000 29.07.26 | S39: ТО-500 23.08.26 | U39: ТО-1000 17.09.26 | X39: ТО-500 12.10.26 | Z39: ТО-2000 06.11.26 | AC39: ТО-500 01.12.26 | AE39: ТО-1000 26.12.26
A40: 30 | C40: 111 | D40: Ник-ка | E40: XCMG XGA5902D3T самосвал | F40: LC1ARMAF4N0701119 | G40: ='Актуальные м.ч.'!E29 -> 12348 | J40: ТО-500 28.05.26 | M40: ТО-1000 22.06.26 | O40: ТО-500 17.07.26 | R40: ТО-2000 11.08.26 | T40: ТО-500 05.09.26 | V40: ТО-1000 30.09.26 | Y40: ТО-500 25.10.26 | AA40: ТО-2000 19.11.26 | AD40: ТО-500 14.12.26
...

Sheet Балхаш
A1: №п/п | B1: Гос.№ | C1: Гараж.№ | D1: участок | E1: Модель техники | F1: WIN | G1: Май | J1: Июнь | M1: Июль | P1: Август | S1: Сентябрь | V1: Октябрь | Y1: Ноябрь | AB1: Декабрь
G2: 1-10 | H2: 11-20 | I2: 21-31 | J2: 1-10 | K2: 11-20 | L2: 21-30 | M2: 1-10 | N2: 11-20 | O2: 21-31 | P2: 1-10 | Q2: 11-20 | R2: 21-31 | S2: 1-10 | T2: 11-20 | U2: 21-30 | V2: 1-10 | W2: 11-20 | X2: 21-31 | Y2: 1-10 | Z2: 11-20 | AA2: 21-30 | AB2: 1-10 | AC2: 11-20 | AD2: 21-31
A3: Балхаш
A4: Топливозаправзики
A5: 1 | D5: Балхаш | E5: Камаз 53215
A6: 2 | D6: Балхаш | E6: Урал 375Д
A7: 3 | D7: Балхаш | E7: Камаз 43118
A8: Погрузчики
A9: 4 | C9: 406 | D9: Балхаш | E9: SDLG 933F | I9: ТО-2000 21.05.26 | J9: ТО-250 03.06.26 | K9: ТО-500 15.06.26 | L9: ТО-250 28.06.26 | M9: ТО-1000 10.07.26 | O9: ТО-250 23.07.26 | P9: ТО-500 04.08.26 | Q9: ТО-250 17.08.26 | R9: ТО-2000 29.08.26 | T9: ТО-250 11.09.26 | U9: ТО-500 23.09.26 | V9: ТО-250 06.10.26 | W9: ТО-1000 18.10.26 | X9: ТО-250 31.10.26 | Z9: ТО-500 12.11.26 | AA9: ТО-250 25.11.26 | AB9: ТО-2000 07.12.26 | AC9: ТО-250 20.12.26
A10: Бульдозеры
A11: 5 | C11: 301 | D11: Балхаш | E11: SD-22 | I11: ТО-1000 30.05.26 | L11: ТО-500 24.06.26 | N11: ТО-2000 19.07.26 | Q11: ТО-500 13.08.26 | S11: ТО-1000 07.09.26 | V11: ТО-500 02.10.26 | X11: ТО-2000 27.10.26 | AA11: ТО-500 21.11.26 | AC11: ТО-1000 16.12.26
A12: 6 | D12: Балхаш | E12: SD-23 | J12: ТО-1000 06.06.26 | M12: ТО-500 01.07.26 | O12: ТО-2000 26.07.26 | Q12: ТО-500 20.08.26 | T12: ТО-1000 14.09.26 | V12: ТО-500 09.10.26 | Y12: ТО-2000 03.11.26 | AA12: ТО-500 28.11.26 | AD12: ТО-1000 23.12.26
A13: 7 | D13: Балхаш | E13: Komatsy D275 | I13: ТО-500 28.05.26 | L13: ТО-1000 22.06.26 | N13: ТО-500 17.07.26 | Q13: ТО-2000 11.08.26 | S13: ТО-500 05.09.26 | U13: ТО-1000 30.09.26 | X13: ТО-500 25.10.26 | Z13: ТО-2000 19.11.26 | AC13: ТО-500 14.12.26
A14: Грейдеры
A15: 8 | D15: Балхаш | E15: автогрейдер SANY STG210C-8S | I15: ТО-250 21.05.26 | J15: ТО-1000 02.06.26 | K15: ТО-250 15.06.26 | L15: ТО-500 27.06.26 | M15: ТО-250 10.07.26 | O15: ТО-2000 22.07.26 | P15: ТО-250 04.08.26 | Q15: ТО-500 16.08.26 | R15: ТО-250 29.08.26 | S15: ТО-1000 10.09.26 | U15: ТО-250 23.09.26 | V15: ТО-500 05.10.26 | W15: ТО-250 18.10.26 | X15: ТО-2000 30.10.26 | Z15: ТО-250 12.11.26 | AA15: ТО-500 24.11.26 | AB15: ТО-250 07.12.26 | AC15: ТО-1000 19.12.26
A16: Каток
A17: 9 | E17: Каток дорожный SANY SSR200C-812 | I17: ТО-250 25.05.26 | J17: ТО-500 07.06.26 | K17: ТО-250 19.06.26 | M17: ТО-1000 02.07.26 | N17: ТО-250 14.07.26 | O17: ТО-500 27.07.26 | P17: ТО-250 08.08.26 | R17: ТО-2000 21.08.26 | S17: ТО-250 02.09.26 | T17: ТО-500 15.09.26 | U17: ТО-250 27.09.26 | V17: ТО-1000 10.10.26 | X17: ТО-250 22.10.26 | Y17: ТО-500 04.11.26 | Z17: ТО-250 16.11.26 | AA17: ТО-2000 29.11.26 | AC17: ТО-250 11.12.26 | AD17: ТО-500 24.12.26
A18: Экскаваторы
A19: 10 | C19: 212 | D19: Балхаш | E19: XCMG 1350 | H19: ТО-250 14.05.26 | I19: ТО-500 26.05.26 | J19: ТО-250 08.06.26 | K19: ТО-1000 20.06.26 | M19: ТО-250 03.07.26 | N19: ТО-500 15.07.26 | O19: ТО-250 28.07.26 | P19: ТО-2000 09.08.26 | R19: ТО-250 22.08.26 | S19: ТО-500 03.09.26 | T19: ТО-250 16.09.26 | U19: ТО-1000 28.09.26 | W19: ТО-250 11.10.26 | X19: ТО-500 23.10.26 | Y19: ТО-250 05.11.26 | Z19: ТО-2000 17.11.26 | AA19: ТО-250 30.11.26 | AC19: ТО-500 12.12.26 | AD19: ТО-250 25.12.26
A20: 11 | C20: 213 | D20: Балхаш | E20: XCMG 1350 | H20: ТО-250 14.05.27 | I20: ТО-500 26.05.27 | J20: ТО-250 08.06.27 | K20: ТО-1000 20.06.27 | M20: ТО-250 03.07.27 | N20: ТО-500 15.07.27 | O20: ТО-250 28.07.27 | P20: ТО-2000 09.08.27 | R20: ТО-250 22.08.27 | S20: ТО-500 03.09.27 | T20: ТО-250 16.09.27 | U20: ТО-1000 28.09.27 | W20: ТО-250 11.10.27 | X20: ТО-500 23.10.27 | Y20: ТО-250 05.11.27 | Z20: ТО-2000 17.11.27 | AA20: ТО-250 30.11.27 | AC20: ТО-500 12.12.27 | AD20: ТО-250 25.12.27
A21: 12 | D21: Балхаш | E21: Volvo 700 | I21: ТО-500 28.05.26 | L21: ТО-1000 22.06.26 | N21: ТО-500 17.07.26 | Q21: ТО-2000 11.08.26 | S21: ТО-500 05.09.26 | U21: ТО-1000 30.09.26 | X21: ТО-500 25.10.26 | Z21: ТО-2000 19.11.26 | AC21: ТО-500 14.12.26
A22: 13 | B22: 455CAND | C22: 207 | D22: Балхаш | E22: HYUNDAI R520LC-9S | I22: ТО-500 27.05.26 | L22: ТО-1000 21.06.26 | N22: ТО-500 16.07.26 | P22: ТО-2000 10.08.26 | S22: ТО-500 04.09.26 | U22: ТО-1000 29.09.26 | X22: ТО-500 24.10.26 | Z22: ТО-2000 18.11.26 | AC22: ТО-500 13.12.26
A23: Самосвалы
A24: 14 | C24: 127 | D24: Балхаш | E24: SANY SKT115S | I24: ТО-2000 22.05.26 | J24: ТО-250 04.06.26 | K24: ТО-500 16.06.26 | L24: ТО-250 29.06.26 | N24: ТО-1000 11.07.26 | O24: ТО-250 24.07.26 | P24: ТО-500 05.08.26 | Q24: ТО-250 18.08.26 | R24: ТО-2000 30.08.26 | T24: ТО-250 12.09.26 | U24: ТО-500 24.09.26 | V24: ТО-250 07.10.26 | W24: ТО-1000 19.10.26 | Y24: ТО-250 01.11.26 | Z24: ТО-500 13.11.26 | AA24: ТО-250 26.11.26 | AB24: ТО-2000 08.12.26 | AD24: ТО-250 21.12.26
A25: 15 | C25: 128 | D25: Балхаш | E25: SANY SKT115S | H25: ТО-2000 17.05.26 | I25: ТО-250 30.05.26 | K25: ТО-500 11.06.26 | L25: ТО-250 24.06.26 | M25: ТО-1000 06.07.26 | N25: ТО-250 19.07.26 | O25: ТО-500 31.07.26 | Q25: ТО-250 13.08.26 | R25: ТО-2000 25.08.26 | S25: ТО-250 07.09.26 | T25: ТО-500 19.09.26 | V25: ТО-250 02.10.26 | W25: ТО-1000 14.10.26 | X25: ТО-250 27.10.26 | Y25: ТО-500 08.11.26 | AA25: ТО-250 21.11.26 | AB25: ТО-2000 03.12.26 | AC25: ТО-250 16.12.26 | AD25: ТО-500 28.12.26
A26: 16 | C26: 129 | D26: Балхаш | E26: SANY SKT115S | I26: ТО-500 24.05.26 | J26: ТО-250 06.06.26 | K26: ТО-2000 18.06.26 | M26: ТО-250 01.07.26 | N26: ТО-500 13.07.26 | O26: ТО-250 26.07.26 | P26: ТО-1000 07.08.26 | Q26: ТО-250 20.08.26 | S26: ТО-500 01.09.26 | T26: ТО-250 14.09.26 | U26: ТО-2000 26.09.26 | V26: ТО-250 09.10.26 | X26: ТО-500 21.10.26 | Y26: ТО-250 03.11.26 | Z26: ТО-1000 15.11.26 | AA26: ТО-250 28.11.26 | AB26: ТО-500 10.12.26 | AD26: ТО-250 23.12.26
A27: 17 | C27: 130 | D27: Балхаш | E27: SANY SKT115S
A28: 18 | C28: 131 | D28: Балхаш | E28: SANY SKT115S | H28: ТО-250 18.05.26 | I28: ТО-500 30.05.26 | K28: ТО-250 12.06.26 | L28: ТО-1000 24.06.26 | M28: ТО-250 07.07.26 | N28: ТО-500 19.07.26 | P28: ТО-250 01.08.26 | Q28: ТО-2000 13.08.26 | R28: ТО-250 26.08.26 | S28: ТО-500 07.09.26 | T28: ТО-250 20.09.26 | V28: ТО-1000 02.10.26 | W28: ТО-250 15.10.26 | X28: ТО-500 27.10.26 | Y28: ТО-250 09.11.26 | AA28: ТО-2000 21.11.26 | AB28: ТО-250 04.12.26 | AC28: ТО-500 16.12.26 | AD28: ТО-250 29.12.26
A29: 19 | C29: 132 | D29: Балхаш | E29: SANY SKT115S | H29: ТО-500 14.05.26 | I29: ТО-250 27.05.26 | J29: ТО-1000 08.06.26 | L29: ТО-250 21.06.26 | M29: ТО-500 03.07.26 | N29: ТО-250 16.07.26 | O29: ТО-2000 28.07.26 | P29: ТО-250 10.08.26 | R29: ТО-500 22.08.26 | S29: ТО-250 04.09.26 | T29: ТО-1000 16.09.26 | U29: ТО-250 29.09.26 | W29: ТО-500 11.10.26 | X29: ТО-250 24.10.26 | Y29: ТО-2000 05.11.26 | Z29: ТО-250 18.11.26 | AA29: ТО-500 30.11.26 | AC29: ТО-250 13.12.26 | AD29: ТО-1000 25.12.26
A30: 20 | C30: 133 | D30: Балхаш | E30: SANY SKT115S | H30: ТО-250 19.05.26 | J30: ТО-1000 01.06.26 | K30: ТО-250 13.06.26 | L30: ТО-500 26.06.26 | M30: ТО-250 08.07.26 | O30: ТО-2000 21.07.26 | P30: ТО-250 02.08.26 | Q30: ТО-500 15.08.26 | R30: ТО-250 27.08.26 | S30: ТО-1000 09.09.26 | U30: ТО-250 21.09.26 | V30: ТО-500 04.10.26 | W30: ТО-250 16.10.26 | X30: ТО-2000 29.10.26 | Y30: ТО-250 10.11.26 | AA30: ТО-500 23.11.26 | AB30: ТО-250 05.12.26 | AC30: ТО-1000 18.12.26 | AD30: ТО-250 30.12.26
A31: 21 | C31: 134 | D31: Балхаш | E31: SANY SKT115S
A32: 22 | C32: 135 | D32: Балхаш | E32: SANY SKT115S | H32: ТО-1000 17.05.26 | I32: ТО-250 29.05.26 | K32: ТО-500 11.06.26 | L32: ТО-250 23.06.26 | M32: ТО-2000 06.07.26 | N32: ТО-250 18.07.26 | O32: ТО-500 31.07.26 | Q32: ТО-250 12.08.26 | R32: ТО-1000 25.08.26 | S32: ТО-250 06.09.26 | T32: ТО-500 19.09.26 | V32: ТО-250 01.10.26 | W32: ТО-2000 14.10.26 | X32: ТО-250 26.10.26 | Y32: ТО-500 08.11.26 | Z32: ТО-250 20.11.26 | AB32: ТО-1000 03.12.26 | AC32: ТО-250 15.12.26 | AD32: ТО-500 28.12.26
A33: 23 | C33: 136 | D33: Балхаш | E33: SANY SKT115S | H33: ТО-250 15.05.26 | I33: ТО-500 28.05.26 | J33: ТО-250 09.06.26 | L33: ТО-1000 22.06.26 | M33: ТО-250 04.07.26 | N33: ТО-500 17.07.26 | O33: ТО-250 29.07.26 | Q33: ТО-2000 11.08.26 | R33: ТО-250 23.08.26 | S33: ТО-500 05.09.26 | T33: ТО-250 17.09.26 | U33: ТО-1000 30.09.26 | W33: ТО-250 12.10.26 | X33: ТО-500 25.10.26 | Y33: ТО-250 06.11.26 | Z33: ТО-2000 19.11.26 | AB33: ТО-250 01.12.26 | AC33: ТО-500 14.12.26 | AD33: ТО-250 26.12.26
A34: 24 | C34: 145 | D34: Балхаш | E34: XCMG XG105 | H34: ТО-1000 16.05.26 | I34: ТО-250 28.05.26 | J34: ТО-500 10.06.26 | L34: ТО-250 22.06.26 | M34: ТО-2000 05.07.26 | N34: ТО-250 17.07.26 | O34: ТО-500 30.07.26 | Q34: ТО-250 11.08.26 | R34: ТО-1000 24.08.26 | S34: ТО-250 05.09.26 | T34: ТО-500 18.09.26 | U34: ТО-250 30.09.26 | W34: ТО-2000 13.10.26 | X34: ТО-250 25.10.26 | Y34: ТО-500 07.11.26 | Z34: ТО-250 19.11.26 | AB34: ТО-1000 02.12.26 | AC34: ТО-250 14.12.26 | AD34: ТО-500 27.12.26

Sheet Актуальные м.ч.
A1: НИКОЛАЕВКА
A2: Техническое обслуживание | G2: Дата моточасов: | H2: 46162
A3: Модели | B3: Борт.№ | C3: Моточасы на момент проведения ТО | D3: Дата проведения ТО | E3: Текущие моточасы | G3: Дата отчета:
A5: Экскаваторы
A6: экскаватор Hitaсhi 470 | B6: 204 | C6: 15000 | D6: 46146 | E6: 15362
A7: XCMG- XE 800 | B7: 209 | C7: 12345 | D7: 46138 | E7: 12686
A8: XCMG- XE 800 | B8: 208 | C8: 15341 | D8: 46138 | E8: 15480
A9: экскаватор Hyndai R 520 (5) | B9: 205 | C9: 3255 | D9: 46158 | E9: 3330
A10: экскаватор Hyndai R 450 | B10: 206 | C10: 6561 | D10: 45962 | E10: 6836
A11: экскаватор Hyndai R 520 (3) | B11: 203 | C11: 47923 | D11: 46138 | E11: 48350
A12: экскаватор Doosan | B12: 211 | C12: 9573 | D12: 46159 | E12: 9630
A13: XCMG- XE 1350 | B13: 214 | C13: 4548 | D13: 46162 | E13: 4548
A14: Бульдозер SEM 832 | B14: 304 | C14: 13242 | D14: 46138 | E14: 13672
A15: Бульдозер SEM 832 | B15: 305 | C15: 13000 | D15: 46141 | E15: 13295
A16: Бульдозер SEM 832 | B16: 307 | C16: 11853 | D16: 46156 | E16: 11957
A17: Бульдозер SEM 832 | B17: 308 | C17: 7311 | D17: 46021 | E17: 7328
... A19: Бульдозер SEM 833 | B19: 310 | C19: 2000 | D19: 46133 | E19: 2215
A20: Cамосвалы XCMG
A21: XCMG | B21: 101 | C21: 14907 | D21: 46057 | E21: 15243
A22: XCMG | B22: 103 | C22: 16739 | D22: 46054 | E22: 17047
A23: XCMG | B23: 104 | C23: 13919 | D23: 46161 | E23: 13936
A24: XCMG | B24: 105 | C24: 12980 | D24: 46153 | E24: 13091
A25: XCMG | B25: 106 | C25: 12680 | D25: 46149 | E25: 12866
A26: XCMG | B26: 108 | C26: 10361 | D26: 45952 | E26: 10488
A27: XCMG | B27: 109 | C27: 11675 | D27: 46056 | E27: 11834
A28: XCMG | B28: 110 | C28: 14418 | D28: 46137 | E28: 14657
A29: XCMG | B29: 111 | C29: 11970 | D29: 46139 | E29: 12348
A30: XCMG | B30: 112 | C30: 11502 | D30: 46138 | E30: 11779
A31: XCMG | B31: 113 | C31: 13440 | D31: 46154 | E31: 13490
A32: XCMG | B32: 114 | C32: 11112 | D32: 46095 | E32: 11261
... A38: XCMG | B38: 120 | C38: 11891 | D38: 46122 | E38: 12365
A39: Самосвалы SANY
A40: SANY | B40: 121 | C40: 7500 | D40: 46083 | E40: 7873
A41: SANY | B41: 122 | C41: 6000 | D41: 46006 | E41: 6066
A42: SANY | B42: 123 | C42: 6037 | D42: 46043 | E42: 6480
A43: SANY | B43: 124 | C43: 8440 | D43: 46147 | E43: 8658
A44: SANY | B44: 125 | C44: 7514 | D44: 46084 | E44: 7915
A45: SANY | B45: 126 | C45: 3200 | D45: 45995 | E45: 3258
A46: Cамосвалы XCMG
A47: XCMG | B47: 137 | C47: 3505 | D47: 46146 | E47: 3883
...
